# エラーハンドリングレビューレポート

## 概要

MBTI 診断チャットアプリケーションのエラーハンドリングを包括的にレビューし、改善案を提示します。

## 現在のエラーハンドリング状況

### 1. データベースドライバー (src/driver/db.py)

#### 現在の問題点：

1. **接続エラーハンドリングの不足**

   - `psycopg2.connect()` の失敗に対する明示的なハンドリングなし
   - 接続プールやリトライ機能なし

2. **SQL 実行エラーハンドリングの不足**

   - `cursor.execute()` の例外処理なし
   - ロールバック処理の未実装

3. **リソース管理の問題**
   - 明示的な接続クローズ処理なし
   - コンテキストマネージャーの不完全な使用

#### 改善提案：

```python
import logging
from typing import Optional, Any
import psycopg2
from psycopg2 import OperationalError, IntegrityError, DataError

logger = logging.getLogger(__name__)

class DatabaseError(Exception):
    """カスタムデータベース例外"""
    pass

class ConnectionError(DatabaseError):
    """データベース接続エラー"""
    pass

class QueryError(DatabaseError):
    """クエリ実行エラー"""
    pass

def get_db_connection():
    """エラーハンドリングを含むデータベース接続取得"""
    try:
        return psycopg2.connect(get_dsn())
    except OperationalError as e:
        logger.error(f"データベース接続エラー: {e}")
        raise ConnectionError(f"データベースに接続できません: {e}")
    except Exception as e:
        logger.error(f"予期しないデータベースエラー: {e}")
        raise DatabaseError(f"データベース操作でエラーが発生しました: {e}")

class ChatSessionDriver:
    def get_or_create_user(self, firebase_uid: str, email: str,
                          display_name: Optional[str] = None,
                          photo_url: Optional[str] = None) -> str:
        """エラーハンドリングを改善したユーザー取得・作成"""
        connection = None
        try:
            connection = get_db_connection()

            with connection.cursor() as cursor:
                # 既存ユーザーの確認
                cursor.execute(
                    "SELECT id FROM users WHERE firebase_uid = %s",
                    (firebase_uid,)
                )
                existing_user = cursor.fetchone()

                if existing_user:
                    user_id = existing_user[0]
                    # ユーザー情報の更新（ログイン時間など）
                    cursor.execute(
                        "UPDATE users SET last_login = now(), email = %s, "
                        "display_name = COALESCE(%s, display_name), "
                        "photo_url = COALESCE(%s, photo_url) WHERE id = %s",
                        (email, display_name, photo_url, user_id)
                    )
                else:
                    # 新規ユーザー作成
                    cursor.execute(
                        "INSERT INTO users (firebase_uid, email, display_name, photo_url) "
                        "VALUES (%s, %s, %s, %s) RETURNING id",
                        (firebase_uid, email, display_name, photo_url)
                    )
                    result = cursor.fetchone()
                    if not result:
                        raise QueryError("ユーザー作成に失敗しました")
                    user_id = result[0]

                connection.commit()
                return user_id

        except IntegrityError as e:
            if connection:
                connection.rollback()
            logger.error(f"データ整合性エラー (firebase_uid: {firebase_uid}): {e}")
            raise QueryError(f"ユーザーデータの整合性エラー: {e}")

        except DataError as e:
            if connection:
                connection.rollback()
            logger.error(f"データ形式エラー (firebase_uid: {firebase_uid}): {e}")
            raise QueryError(f"無効なデータ形式: {e}")

        except Exception as e:
            if connection:
                connection.rollback()
            logger.error(f"ユーザー操作エラー (firebase_uid: {firebase_uid}): {e}")
            raise DatabaseError(f"ユーザー操作でエラーが発生しました: {e}")

        finally:
            if connection:
                connection.close()
```

### 2. LangGraph ドライバー (src/driver/langgraph_driver.py)

#### 現在の問題点：

1. **LLM 呼び出しエラーハンドリングの不足**

   - OpenAI API エラーの適切な処理なし
   - レート制限やタイムアウトへの対応なし

2. **ワークフロー実行エラーハンドリングの不完全性**
   - 中間状態での例外処理不足
   - 部分的失敗からの復旧機能なし

#### 改善提案：

```python
import asyncio
from openai import OpenAIError, RateLimitError, APITimeoutError
from tenacity import retry, stop_after_attempt, wait_exponential

class WorkflowError(Exception):
    """ワークフロー実行エラー"""
    pass

class LLMError(WorkflowError):
    """LLM呼び出しエラー"""
    pass

class LangGraphDriver:
    @retry(
        stop=stop_after_attempt(3),
        wait=wait_exponential(multiplier=1, min=4, max=10)
    )
    async def _call_llm_with_retry(self, operation, *args, **kwargs):
        """リトライ機能付きLLM呼び出し"""
        try:
            return await operation(*args, **kwargs)
        except RateLimitError as e:
            logger.warning(f"レート制限エラー、リトライします: {e}")
            raise
        except APITimeoutError as e:
            logger.warning(f"タイムアウトエラー、リトライします: {e}")
            raise
        except OpenAIError as e:
            logger.error(f"OpenAI APIエラー: {e}")
            raise LLMError(f"LLM呼び出しエラー: {e}")

    def _generate_question_node(self, state: dict) -> dict:
        """エラーハンドリングを改善した質問生成"""
        try:
            # フィルタリングされたメッセージの取得
            filtered_messages = self._filter_messages_by_phase(
                state.get("messages", []),
                state.get("next_display_order", 1)
            )

            # LLM呼び出し
            question = self._call_llm_with_retry(
                self.llm_port.generate_question,
                self._format_messages_for_llm(filtered_messages),
                state.get("personality_element_id", 1)
            )

            if not question or not question.strip():
                raise WorkflowError("空の質問が生成されました")

            # データベース保存
            question_id = self.question_repo.save_question(
                state["session_id"],
                state["next_display_order"],
                question,
                state["personality_element_id"]
            )

            if not question_id:
                raise WorkflowError("質問の保存に失敗しました")

            return {
                **state,
                "current_question": question,
                "current_question_id": question_id
            }

        except LLMError:
            # LLMエラーは再発生させる（リトライ対象）
            raise
        except Exception as e:
            logger.error(f"質問生成ノードエラー: {e}")
            raise WorkflowError(f"質問生成に失敗しました: {e}")
```

### 3. MBTI サービス (src/usecase/mbti_service.py)

#### 現在の問題点：

1. **ビジネスロジック例外の未定義**
   - セッション状態の不整合処理なし
   - 無効な診断状態への対応不足

#### 改善提案：

```python
class MBTIServiceError(Exception):
    """MBTIサービス例外基底クラス"""
    pass

class SessionStateError(MBTIServiceError):
    """セッション状態エラー"""
    pass

class DiagnosisError(MBTIServiceError):
    """診断処理エラー"""
    pass

class MBTIService:
    async def start_diagnosis(self, user_request: StartDiagnosisRequest) -> StartDiagnosisResponse:
        """エラーハンドリングを改善した診断開始"""
        try:
            # セッション取得・作成
            session_id = await self._get_or_create_session(user_request)
            if not session_id:
                raise SessionStateError("セッションの作成に失敗しました")

            # ワークフロー実行
            result = await self.workflow.run_workflow(
                session_id,
                user_request.personality_element_id
            )

            if not result or not result.get("current_question"):
                raise DiagnosisError("最初の質問の生成に失敗しました")

            return StartDiagnosisResponse(
                session_id=session_id,
                question=result["current_question"],
                question_id=result["current_question_id"],
                options=result.get("options", [])
            )

        except (SessionStateError, DiagnosisError):
            # ビジネスロジックエラーは再発生
            raise
        except Exception as e:
            logger.error(f"診断開始エラー: {e}")
            raise MBTIServiceError(f"診断開始処理でエラーが発生しました: {e}")
```

## 推奨される改善順序

1. **最優先**: データベースドライバーのエラーハンドリング改善

   - 接続エラー、SQL 実行エラーの適切な処理
   - ロールバック機能の実装

2. **高優先**: LangGraph ドライバーの LLM 呼び出しエラーハンドリング

   - リトライ機能の実装
   - OpenAI API エラーの分類と対応

3. **中優先**: MBTI サービスのビジネスロジック例外

   - カスタム例外クラスの定義
   - 適切なエラーメッセージの提供

4. **低優先**: 統合的なエラー監視
   - ログ集約システムの導入
   - メトリクス収集の実装

## まとめ

現在のエラーハンドリングは基本的な機能は動作するものの、本格運用には不十分です。特にデータベース操作と LLM 呼び出しの部分で、エラーの適切な分類、ログ記録、復旧処理が必要です。
